[2024-06-10T09:17:29.044+0000] {local_task_job_runner.py:120} INFO - ::group::Pre task execution logs
[2024-06-10T09:17:29.065+0000] {taskinstance.py:2076} INFO - Dependencies all met for dep_context=non-requeueable deps ti=<TaskInstance: test_postgresql_connection_1.test_postgresql_connection_task manual__2024-06-10T09:17:27.814009+00:00 [queued]>
[2024-06-10T09:17:29.069+0000] {taskinstance.py:2076} INFO - Dependencies all met for dep_context=requeueable deps ti=<TaskInstance: test_postgresql_connection_1.test_postgresql_connection_task manual__2024-06-10T09:17:27.814009+00:00 [queued]>
[2024-06-10T09:17:29.069+0000] {taskinstance.py:2306} INFO - Starting attempt 1 of 2
[2024-06-10T09:17:29.076+0000] {taskinstance.py:2330} INFO - Executing <Task(PythonOperator): test_postgresql_connection_task> on 2024-06-10 09:17:27.814009+00:00
[2024-06-10T09:17:29.082+0000] {logging_mixin.py:188} WARNING - /home/***/.local/lib/python3.12/site-packages/***/task/task_runner/standard_task_runner.py:61 DeprecationWarning: This process (pid=901) is multi-threaded, use of fork() may lead to deadlocks in the child.
[2024-06-10T09:17:29.080+0000] {standard_task_runner.py:90} INFO - Running: ['***', 'tasks', 'run', 'test_postgresql_connection_1', 'test_postgresql_connection_task', 'manual__2024-06-10T09:17:27.814009+00:00', '--job-id', '15', '--raw', '--subdir', 'DAGS_FOLDER/dag_testconnection.py', '--cfg-path', '/tmp/tmp5q2wu449']
[2024-06-10T09:17:29.082+0000] {standard_task_runner.py:63} INFO - Started process 902 to run task
[2024-06-10T09:17:29.082+0000] {standard_task_runner.py:91} INFO - Job 15: Subtask test_postgresql_connection_task
[2024-06-10T09:17:29.117+0000] {task_command.py:426} INFO - Running <TaskInstance: test_postgresql_connection_1.test_postgresql_connection_task manual__2024-06-10T09:17:27.814009+00:00 [running]> on host 5f414d64f7b6
[2024-06-10T09:17:29.159+0000] {taskinstance.py:2648} INFO - Exporting env vars: AIRFLOW_CTX_DAG_EMAIL='***@example.com' AIRFLOW_CTX_DAG_OWNER='***' AIRFLOW_CTX_DAG_ID='test_postgresql_connection_1' AIRFLOW_CTX_TASK_ID='test_postgresql_connection_task' AIRFLOW_CTX_EXECUTION_DATE='2024-06-10T09:17:27.814009+00:00' AIRFLOW_CTX_TRY_NUMBER='1' AIRFLOW_CTX_DAG_RUN_ID='manual__2024-06-10T09:17:27.814009+00:00'
[2024-06-10T09:17:29.160+0000] {taskinstance.py:430} INFO - ::endgroup::
[2024-06-10T09:17:29.183+0000] {base.py:84} INFO - Using connection ID 'postgres_conn' for task execution.
[2024-06-10T09:17:29.185+0000] {logging_mixin.py:188} INFO - Koneksi gagal: connection to server at "localhost" (::1), port 5434 failed: Connection refused
	Is the server running on that host and accepting TCP/IP connections?
connection to server at "localhost" (127.0.0.1), port 5434 failed: Connection refused
	Is the server running on that host and accepting TCP/IP connections?
[2024-06-10T09:17:29.185+0000] {taskinstance.py:441} INFO - ::group::Post task execution logs
[2024-06-10T09:17:29.185+0000] {taskinstance.py:2905} ERROR - Task failed with exception
Traceback (most recent call last):
  File "/home/airflow/.local/lib/python3.12/site-packages/airflow/models/taskinstance.py", line 465, in _execute_task
    result = _execute_callable(context=context, **execute_callable_kwargs)
             ^^^^^^^^^^^^^^^^^^^^^^^^^^^^^^^^^^^^^^^^^^^^^^^^^^^^^^^^^^^^^
  File "/home/airflow/.local/lib/python3.12/site-packages/airflow/models/taskinstance.py", line 432, in _execute_callable
    return execute_callable(context=context, **execute_callable_kwargs)
           ^^^^^^^^^^^^^^^^^^^^^^^^^^^^^^^^^^^^^^^^^^^^^^^^^^^^^^^^^^^^
  File "/home/airflow/.local/lib/python3.12/site-packages/airflow/models/baseoperator.py", line 400, in wrapper
    return func(self, *args, **kwargs)
           ^^^^^^^^^^^^^^^^^^^^^^^^^^^
  File "/home/airflow/.local/lib/python3.12/site-packages/airflow/operators/python.py", line 235, in execute
    return_value = self.execute_callable()
                   ^^^^^^^^^^^^^^^^^^^^^^^
  File "/home/airflow/.local/lib/python3.12/site-packages/airflow/operators/python.py", line 252, in execute_callable
    return self.python_callable(*self.op_args, **self.op_kwargs)
           ^^^^^^^^^^^^^^^^^^^^^^^^^^^^^^^^^^^^^^^^^^^^^^^^^^^^^
  File "/opt/airflow/dags/dag_testconnection.py", line 20, in test_postgresql_connection
    if connection:
       ^^^^^^^^^^
UnboundLocalError: cannot access local variable 'connection' where it is not associated with a value
[2024-06-10T09:17:29.192+0000] {taskinstance.py:1206} INFO - Marking task as UP_FOR_RETRY. dag_id=test_postgresql_connection_1, task_id=test_postgresql_connection_task, run_id=manual__2024-06-10T09:17:27.814009+00:00, execution_date=20240610T091727, start_date=20240610T091729, end_date=20240610T091729
[2024-06-10T09:17:29.198+0000] {standard_task_runner.py:110} ERROR - Failed to execute job 15 for task test_postgresql_connection_task (cannot access local variable 'connection' where it is not associated with a value; 902)
[2024-06-10T09:17:29.228+0000] {local_task_job_runner.py:240} INFO - Task exited with return code 1
[2024-06-10T09:17:29.236+0000] {taskinstance.py:3498} INFO - 0 downstream tasks scheduled from follow-on schedule check
[2024-06-10T09:17:29.236+0000] {local_task_job_runner.py:222} INFO - ::endgroup::
