[2024-06-11T04:51:06.477+0000] {local_task_job_runner.py:120} INFO - ::group::Pre task execution logs
[2024-06-11T04:51:06.494+0000] {taskinstance.py:2076} INFO - Dependencies all met for dep_context=non-requeueable deps ti=<TaskInstance: mssql_to_postgresql_05.load_to_postgresql scheduled__2024-06-10T00:00:00+00:00 [queued]>
[2024-06-11T04:51:06.498+0000] {taskinstance.py:2076} INFO - Dependencies all met for dep_context=requeueable deps ti=<TaskInstance: mssql_to_postgresql_05.load_to_postgresql scheduled__2024-06-10T00:00:00+00:00 [queued]>
[2024-06-11T04:51:06.498+0000] {taskinstance.py:2306} INFO - Starting attempt 1 of 1
[2024-06-11T04:51:06.504+0000] {taskinstance.py:2330} INFO - Executing <Task(PythonOperator): load_to_postgresql> on 2024-06-10 00:00:00+00:00
[2024-06-11T04:51:06.510+0000] {standard_task_runner.py:90} INFO - Running: ['***', 'tasks', 'run', 'mssql_to_postgresql_05', 'load_to_postgresql', 'scheduled__2024-06-10T00:00:00+00:00', '--job-id', '28', '--raw', '--subdir', 'DAGS_FOLDER/copy_file_transfer.py', '--cfg-path', '/tmp/tmpgvfl9cdj']
[2024-06-11T04:51:06.511+0000] {logging_mixin.py:188} WARNING - /home/***/.local/lib/python3.12/site-packages/***/task/task_runner/standard_task_runner.py:61 DeprecationWarning: This process (pid=1171) is multi-threaded, use of fork() may lead to deadlocks in the child.
[2024-06-11T04:51:06.512+0000] {standard_task_runner.py:91} INFO - Job 28: Subtask load_to_postgresql
[2024-06-11T04:51:06.512+0000] {standard_task_runner.py:63} INFO - Started process 1172 to run task
[2024-06-11T04:51:06.534+0000] {task_command.py:426} INFO - Running <TaskInstance: mssql_to_postgresql_05.load_to_postgresql scheduled__2024-06-10T00:00:00+00:00 [running]> on host 2e5c63130483
[2024-06-11T04:51:06.570+0000] {taskinstance.py:2648} INFO - Exporting env vars: AIRFLOW_CTX_DAG_OWNER='***' AIRFLOW_CTX_DAG_ID='mssql_to_postgresql_05' AIRFLOW_CTX_TASK_ID='load_to_postgresql' AIRFLOW_CTX_EXECUTION_DATE='2024-06-10T00:00:00+00:00' AIRFLOW_CTX_TRY_NUMBER='1' AIRFLOW_CTX_DAG_RUN_ID='scheduled__2024-06-10T00:00:00+00:00'
[2024-06-11T04:51:06.570+0000] {taskinstance.py:430} INFO - ::endgroup::
[2024-06-11T04:51:06.586+0000] {base.py:84} INFO - Using connection ID 'postgres_conn' for task execution.
[2024-06-11T04:51:06.589+0000] {sql.py:470} INFO - Running statement: 
    INSERT INTO raw_data.cybertrack_superapps_v_transfer (
        "Id", 
        "TransactionID", 
        "TransactionDatetime", 
        "TransactionType", 
        "TransactionAmount", 
        "TransactionStatus", 
        "SourceAccountId", 
        "SourceAccountName", 
        "SourceAccountType", 
        "DestinationAccountId", 
        "DestinationAccountName", 
        "DestinationAccountBank", 
        "TransactionCategory", 
        "AccountCIFNo", 
        "AccountPhoneNo", 
        "AccountEmail", 
        "SourceAccountStatus"
    ) VALUES (%s, %s, %s, %s, %s, %s, %s, %s, %s, %s, %s, %s, %s, %s, %s, %s, %s)
    , parameters: (1023441, 'TB2024061078062253', datetime.datetime(2024, 6, 10, 22, 48, 38, 970000))
[2024-06-11T04:51:06.590+0000] {taskinstance.py:441} INFO - ::group::Post task execution logs
[2024-06-11T04:51:06.590+0000] {taskinstance.py:2905} ERROR - Task failed with exception
Traceback (most recent call last):
  File "/home/airflow/.local/lib/python3.12/site-packages/airflow/models/taskinstance.py", line 465, in _execute_task
    result = _execute_callable(context=context, **execute_callable_kwargs)
             ^^^^^^^^^^^^^^^^^^^^^^^^^^^^^^^^^^^^^^^^^^^^^^^^^^^^^^^^^^^^^
  File "/home/airflow/.local/lib/python3.12/site-packages/airflow/models/taskinstance.py", line 432, in _execute_callable
    return execute_callable(context=context, **execute_callable_kwargs)
           ^^^^^^^^^^^^^^^^^^^^^^^^^^^^^^^^^^^^^^^^^^^^^^^^^^^^^^^^^^^^
  File "/home/airflow/.local/lib/python3.12/site-packages/airflow/models/baseoperator.py", line 400, in wrapper
    return func(self, *args, **kwargs)
           ^^^^^^^^^^^^^^^^^^^^^^^^^^^
  File "/home/airflow/.local/lib/python3.12/site-packages/airflow/operators/python.py", line 235, in execute
    return_value = self.execute_callable()
                   ^^^^^^^^^^^^^^^^^^^^^^^
  File "/home/airflow/.local/lib/python3.12/site-packages/airflow/operators/python.py", line 252, in execute_callable
    return self.python_callable(*self.op_args, **self.op_kwargs)
           ^^^^^^^^^^^^^^^^^^^^^^^^^^^^^^^^^^^^^^^^^^^^^^^^^^^^^
  File "/opt/airflow/dags/copy_file_transfer.py", line 56, in load_to_postgresql
    pg_hook.run(insert_query, parameters=(record[0], record[1], record[2]))
  File "/home/airflow/.local/lib/python3.12/site-packages/airflow/providers/common/sql/hooks/sql.py", line 418, in run
    self._run_command(cur, sql_statement, parameters)
  File "/home/airflow/.local/lib/python3.12/site-packages/airflow/providers/common/sql/hooks/sql.py", line 473, in _run_command
    cur.execute(sql_statement, parameters)
IndexError: tuple index out of range
[2024-06-11T04:51:06.597+0000] {taskinstance.py:1206} INFO - Marking task as FAILED. dag_id=mssql_to_postgresql_05, task_id=load_to_postgresql, run_id=scheduled__2024-06-10T00:00:00+00:00, execution_date=20240610T000000, start_date=20240611T045106, end_date=20240611T045106
[2024-06-11T04:51:06.603+0000] {standard_task_runner.py:110} ERROR - Failed to execute job 28 for task load_to_postgresql (tuple index out of range; 1172)
[2024-06-11T04:51:06.612+0000] {local_task_job_runner.py:240} INFO - Task exited with return code 1
[2024-06-11T04:51:06.620+0000] {taskinstance.py:3498} INFO - 0 downstream tasks scheduled from follow-on schedule check
[2024-06-11T04:51:06.621+0000] {local_task_job_runner.py:222} INFO - ::endgroup::
